<?xml version="1.0" encoding="utf-8"?>
<!-- This URDF was automatically created by SolidWorks to URDF Exporter! Originally created by Stephen Brawner (brawner@gmail.com) 
     Commit Version: 1.6.0-4-g7f85cfe  Build Version: 1.6.7995.38578
     For more information, please see http://wiki.ros.org/sw_urdf_exporter -->
<robot
  name="orca_ydescription">
<material name="black">
  <color rgba="0.0 0.0 0.0 1.0"/>
</material>
<material name="blue">
  <color rgba="0.0 0.0 0.8 1.0"/>
</material>
<material name="green">
  <color rgba="0.0 0.8 0.0 1.0"/>
</material>
<material name="grey">
  <color rgba="0.2 0.2 0.2 1.0"/>
</material>
<material name="silver">
  <color rgba="0.9137254901960784 0.9137254901960784 0.8470588235294118 1.0"/>
</material>
<material name="orange">
  <color rgba="1.0 0.4235294117647059 0.0392156862745098 1.0"/>
</material>
<material name="brown">
  <color rgba="0.8705882352941177 0.8117647058823529 0.7647058823529411 1.0"/>
</material>
<material name="red">
  <color rgba="0.8 0.0 0.0 1.0"/>
</material>
<material name="white">
  <color rgba="1.0 1.0 1.0 1.0"/>
</material>
  <!-- <link name="world" />
  <joint name ="base_static_joint" type="fixed">
    <parent link="world"/>
    <child link="base"/>
    <origin xyz="0 0 0.5"/>
  </joint> -->
  <gazebo>
    <plugin filename="libhm_hw_sim.so" name="gazebo_ros_control">
      <robotNamespace>/</robotNamespace>
      <robotParam>hm_description</robotParam>
      <robotSimType>hm_gazebo/HmHWSimWoRegister</robotSimType>
    </plugin>
  </gazebo>
  <!-- Show the trajectory of trunk center. -->
  <gazebo>
    <plugin filename="libLinkPlot3DPlugin.so" name="3dplot">
      <frequency>10</frequency>
      <plot>
        <link>base</link>
        <pose>0 0 0 0 0 0</pose>
        <material>Gazebo/Yellow</material>
      </plot>
    </plugin>
  </gazebo>
  <gazebo>
    <plugin filename="libgazebo_ros_force.so" name="gazebo_ros_force">
      <bodyName>base_link</bodyName>
      <topicName>/apply_force/base_link</topicName>
    </plugin>
  </gazebo> 

  <!-- ************************************************************ -->
  <!-- ************************base Gazebo ************************** -->
  <!-- ************************************************************ -->
  <gazebo reference="base">
    <material>Gazebo/Green</material>
    <turnGravityOff>false</turnGravityOff>
  </gazebo>
  <gazebo reference="base_link">
    <mu1>0.2</mu1>
    <mu2>0.2</mu2>
    <material>Gazebo/DarkGrey</material>
  </gazebo>
  <gazebo reference="imu_link">
    <mu1>1</mu1>
    <mu2>1</mu2>
    <material>Gazebo/Red</material>
  </gazebo>
  <gazebo reference="imu_joint">
    <disableFixedJointLumping>true</disableFixedJointLumping>
  </gazebo>
 <!-- ************************************************************ -->
  <!-- ************************ Left Leg Gazebo ************************** -->
  <!-- ************************************************************ -->
  <gazebo reference="lleg_link1">
    <mu1>1</mu1>
    <mu2>1</mu2>
    <kp value="100000.0"/>
    <kd value="1000.0"/>
    <material>Gazebo/Grey</material>
  </gazebo>
  <gazebo reference="lleg_link2">
    <mu1>1</mu1>
    <mu2>1</mu2>
    <kp value="100000.0"/>
    <kd value="1000.0"/>
    <material>Gazebo/Grey</material>
  </gazebo>
  <gazebo reference="lleg_link3">
    <mu1>1</mu1>
    <mu2>1</mu2>
    <kp value="100000.0"/>
    <kd value="1000.0"/>
    <self_collide>0</self_collide>
    <material>Gazebo/Grey</material>
  </gazebo>
  <gazebo reference="lleg_link4">
    <mu1>1</mu1>
    <mu2>1</mu2>
    <kp value="100000.0"/>
    <kd value="1000.0"/>
    <self_collide>0</self_collide>
    <material>Gazebo/Grey</material>
  </gazebo>
  <gazebo reference="lleg_link5">
    <mu1>3</mu1>
    <mu2>3</mu2>
    <kp value="1000000.0"/>
    <kd value="1000.0"/>
    <self_collide>0</self_collide>
    <material>Gazebo/Grey</material>
  </gazebo>
  <gazebo reference="lleg_link6">
    <mu1>3</mu1>
    <mu2>3</mu2>
    <kp value="1000000.0"/>
    <kd value="1000.0"/>
    <self_collide>0</self_collide>
    <material>Gazebo/Grey</material>
  </gazebo>
<!-- ************************************************************ -->
  <!-- ************************ Right Leg Gazebo ************************** -->
  <!-- ************************************************************ -->
  <gazebo reference="rleg_link1">
    <mu1>1</mu1>
    <mu2>1</mu2>
    <kp value="100000.0"/>
    <kd value="1000.0"/>
    <material>Gazebo/Grey</material>
  </gazebo>
  <gazebo reference="rleg_link2">
    <mu1>1</mu1>
    <mu2>1</mu2>
    <kp value="100000.0"/>
    <kd value="1000.0"/>
    <material>Gazebo/Grey</material>
  </gazebo>
  <gazebo reference="rleg_link3">
    <mu1>1</mu1>
    <mu2>1</mu2>
    <kp value="100000.0"/>
    <kd value="1000.0"/>
    <self_collide>0</self_collide>
    <material>Gazebo/Grey</material>
  </gazebo>
  <gazebo reference="rleg_link4">
    <mu1>1</mu1>
    <mu2>1</mu2>
    <kp value="100000.0"/>
    <kd value="1000.0"/>
    <self_collide>0</self_collide>
    <material>Gazebo/Grey</material>
  </gazebo>
  <gazebo reference="rleg_link5">
    <mu1>3</mu1>
    <mu2>3</mu2>
    <kp value="1000000.0"/>
    <kd value="1000.0"/>
    <self_collide>0</self_collide>
    <material>Gazebo/Grey</material>
  </gazebo>
  <gazebo reference="rleg_link6">
    <mu1>3</mu1>
    <mu2>3</mu2>
    <kp value="1000000.0"/>
    <kd value="1000.0"/>
    <self_collide>0</self_collide>
    <material>Gazebo/Grey</material>
  </gazebo>  
  <!-- ************************************************************ -->
  <!-- ************************ Left Arm Gazebo ************************** -->
  <!-- ************************************************************ -->
  <gazebo reference="larm_link1">
    <mu1>1</mu1>
    <mu2>1</mu2>
    <kp value="100000.0"/>
    <kd value="1000.0"/>
    <material>Gazebo/Grey</material>
  </gazebo>
  <gazebo reference="larm_link2">
    <mu1>1</mu1>
    <mu2>1</mu2>
    <kp value="100000.0"/>
    <kd value="1000.0"/>
    <material>Gazebo/Grey</material>
  </gazebo>
  <gazebo reference="larm_link3">
    <mu1>1</mu1>
    <mu2>1</mu2>
    <kp value="100000.0"/>
    <kd value="1000.0"/>
    <self_collide>0</self_collide>
    <material>Gazebo/Grey</material>
  </gazebo>
  <gazebo reference="larm_link4">
    <mu1>1</mu1>
    <mu2>1</mu2>
    <kp value="100000.0"/>
    <kd value="1000.0"/>
    <self_collide>0</self_collide>
    <material>Gazebo/Grey</material>
  </gazebo>
  <gazebo reference="larm_link5">
    <mu1>3</mu1>
    <mu2>3</mu2>
    <kp value="1000000.0"/>
    <kd value="1000.0"/>
    <self_collide>0</self_collide>
    <material>Gazebo/Grey</material>
  </gazebo>
    <gazebo reference="larm_link6">
    <mu1>3</mu1>
    <mu2>3</mu2>
    <kp value="1000000.0"/>
    <kd value="1000.0"/>
    <self_collide>0</self_collide>
    <material>Gazebo/Grey</material>
  </gazebo>
  <!-- ************************************************************ -->
  <!-- ************************ Right Arm Gazebo ************************** -->
  <!-- ************************************************************ -->
  <gazebo reference="rarm_link1">
    <mu1>1</mu1>
    <mu2>1</mu2>
    <kp value="100000.0"/>
    <kd value="1000.0"/>
    <material>Gazebo/Grey</material>
  </gazebo>
  <gazebo reference="rarm_link2">
    <mu1>1</mu1>
    <mu2>1</mu2>
    <kp value="100000.0"/>
    <kd value="1000.0"/>
    <material>Gazebo/Grey</material>
  </gazebo>
  <gazebo reference="rarm_link3">
    <mu1>1</mu1>
    <mu2>1</mu2>
    <kp value="100000.0"/>
    <kd value="1000.0"/>
    <self_collide>0</self_collide>
    <material>Gazebo/Grey</material>
  </gazebo>
  <gazebo reference="rarm_link4">
    <mu1>1</mu1>
    <mu2>1</mu2>
    <kp value="100000.0"/>
    <kd value="1000.0"/>
    <self_collide>0</self_collide>
    <material>Gazebo/Grey</material>
  </gazebo>
  <gazebo reference="rarm_link5">
    <mu1>3</mu1>
    <mu2>3</mu2>
    <kp value="1000000.0"/>
    <kd value="1000.0"/>
    <self_collide>0</self_collide>
    <material>Gazebo/Grey</material>
  </gazebo>
    <gazebo reference="rarm_link6">
    <mu1>3</mu1>
    <mu2>3</mu2>
    <kp value="1000000.0"/>
    <kd value="1000.0"/>
    <self_collide>0</self_collide>
    <material>Gazebo/Grey</material>
  </gazebo>  
  <!-- ************************************************************ -->
  <!-- ************************ Waist yaw Gazebo ************************** -->
  <!-- ************************************************************ -->  
  <gazebo reference="waist_yaw_link">
    <mu1>3</mu1>
    <mu2>3</mu2>
    <kp value="1000000.0"/>
    <kd value="1000.0"/>
    <self_collide>0</self_collide>
    <material>Gazebo/Grey</material>
  </gazebo>
  <!-- ************************************************************ -->
  <!-- ************************ end Waist yaw Gazebo ************************** -->
  <!-- ************************************************************ -->
  <gazebo reference="head_link1">
    <!-- head yaw -->
    <mu1>3</mu1>
    <mu2>3</mu2>
    <kp value="1000000.0"/>
    <kd value="1000.0"/>
    <self_collide>0</self_collide>
    <material>Gazebo/Grey</material>
  </gazebo>
  <gazebo reference="head_link2">
    <!-- head roll -->
    <mu1>3</mu1>
    <mu2>3</mu2>
    <kp value="1000000.0"/>
    <kd value="1000.0"/>
    <self_collide>0</self_collide>
    <material>Gazebo/Grey</material>
  </gazebo>
  <gazebo reference="head_link3">
    <!-- head pitch -->
    <mu1>3</mu1>
    <mu2>3</mu2>
    <kp value="1000000.0"/>
    <kd value="1000.0"/>
    <self_collide>0</self_collide>
    <material>Gazebo/Grey</material>
  </gazebo>
  <!-- Lleg Gazebo Parts-->

  <gazebo reference="lleg_joint6_fixed_1">
    <mu1>1.5</mu1>
    <mu2>1.5</mu2>
    <self_collide>1</self_collide>
    <kp value="1000000.0"/>
    <kd value="100.0"/>
    <maxVel>1.0</maxVel>
    <minDepth>0.00</minDepth>
  </gazebo>
  <gazebo reference="lleg_link6_fixed2">
    <mu1>1.5</mu1>
    <mu2>1.5</mu2>
    <self_collide>1</self_collide>
    <kp value="1000000.0"/>
    <kd value="100.0"/>
    <maxVel>1.0</maxVel>
    <minDepth>0.00</minDepth>
  </gazebo>
  
  <transmission name="lleg_joint1_tran">
    <type>transmission_interface/SimpleTransmission</type>
    <joint name="lleg_joint1">
      <hardwareInterface>hardware_interface/EffortJointInterface</hardwareInterface>
    </joint>
    <actuator name="lleg_joint1_motor">
      <hardwareInterface>hardware_interface/EffortJointInterface</hardwareInterface>
      <mechanicalReduction>1</mechanicalReduction>
    <maxVelocity>14.65</maxVelocity><!-- 140rpm -->
    <maxEffort>150.0</maxEffort><!-- 150Nm -->
    </actuator>
  </transmission>
  
  <transmission name="lleg_joint2_tran">
    <type>transmission_interface/SimpleTransmission</type>
    <joint name="lleg_joint2">
      <hardwareInterface>hardware_interface/EffortJointInterface</hardwareInterface>
    </joint>
    <actuator name="lleg_joint2_motor">
      <hardwareInterface>hardware_interface/EffortJointInterface</hardwareInterface>
      <mechanicalReduction>1</mechanicalReduction>
    <maxVelocity>15.70</maxVelocity><!-- 150rpm -->
    <maxEffort>94.0</maxEffort><!-- 94Nm -->
    </actuator>
  </transmission>
  <transmission name="lleg_joint3_tran">
    <type>transmission_interface/SimpleTransmission</type>
    <joint name="lleg_joint3">
      <hardwareInterface>hardware_interface/EffortJointInterface</hardwareInterface>
    </joint>
    <actuator name="lleg_joint3_motor">
      <hardwareInterface>hardware_interface/EffortJointInterface</hardwareInterface>
      <mechanicalReduction>1</mechanicalReduction>
    <maxVelocity>15.70</maxVelocity><!-- 150rpm -->
    <maxEffort>94.0</maxEffort><!-- 94Nm -->
    </actuator>
  </transmission>
  <transmission name="lleg_joint4_tran">
    <type>transmission_interface/SimpleTransmission</type>
    <joint name="lleg_joint4">
      <hardwareInterface>hardware_interface/EffortJointInterface</hardwareInterface>
    </joint>
    <actuator name="lleg_joint4_motor">
      <hardwareInterface>hardware_interface/EffortJointInterface</hardwareInterface>
      <mechanicalReduction>1</mechanicalReduction>
    <maxVelocity>12.56</maxVelocity><!-- 150rpm -->
    <maxEffort>150.0</maxEffort><!-- 150Nm -->
    </actuator>
  </transmission>
  <transmission name="lleg_joint5_tran">
    <type>transmission_interface/SimpleTransmission</type>
    <joint name="lleg_joint5">
      <hardwareInterface>hardware_interface/EffortJointInterface</hardwareInterface>
    </joint>
    <actuator name="lleg_joint5_motor">
      <hardwareInterface>hardware_interface/EffortJointInterface</hardwareInterface>
      <mechanicalReduction>1</mechanicalReduction>
    <maxVelocity>8.97</maxVelocity><!-- 85rpm -->
    <maxEffort>36.0</maxEffort><!-- 36Nm -->
    </actuator>
  </transmission>
  <transmission name="lleg_joint6_tran">
    <type>transmission_interface/SimpleTransmission</type>
    <joint name="lleg_joint6">
      <hardwareInterface>hardware_interface/EffortJointInterface</hardwareInterface>
    </joint>
    <actuator name="lleg_joint6_motor">
      <hardwareInterface>hardware_interface/EffortJointInterface</hardwareInterface>
      <mechanicalReduction>1</mechanicalReduction>
    <maxVelocity>8.97</maxVelocity><!-- 85rpm -->
    <maxEffort>36.0</maxEffort><!-- 36Nm -->
    </actuator>
  </transmission>
  <!-- Rleg Gazebo Parts-->

<gazebo reference="rleg_joint6_fixed_1">
  <mu1>1.5</mu1>
  <mu2>1.5</mu2>
  <self_collide>1</self_collide>
  <kp value="1000000.0"/>
  <kd value="100.0"/>
  <maxVel>1.0</maxVel>
  <minDepth>0.00</minDepth>
</gazebo>
<gazebo reference="rleg_link6_fixed2">
  <mu1>1.5</mu1>
  <mu2>1.5</mu2>
  <self_collide>1</self_collide>
  <kp value="1000000.0"/>
  <kd value="100.0"/>
  <maxVel>1.0</maxVel>
  <minDepth>0.00</minDepth>
</gazebo>

<transmission name="rleg_joint1_tran">
  <type>transmission_interface/SimpleTransmission</type>
  <joint name="rleg_joint1">
    <hardwareInterface>hardware_interface/EffortJointInterface</hardwareInterface>
  </joint>
  <actuator name="rleg_joint1_motor">
    <hardwareInterface>hardware_interface/EffortJointInterface</hardwareInterface>
    <mechanicalReduction>1</mechanicalReduction>
  <maxVelocity>14.65</maxVelocity><!-- 140rpm -->
  <maxEffort>150.0</maxEffort><!-- 150Nm -->
  </actuator>
</transmission>

<transmission name="rleg_joint2_tran">
  <type>transmission_interface/SimpleTransmission</type>
  <joint name="rleg_joint2">
    <hardwareInterface>hardware_interface/EffortJointInterface</hardwareInterface>
  </joint>
  <actuator name="rleg_joint2_motor">
    <hardwareInterface>hardware_interface/EffortJointInterface</hardwareInterface>
    <mechanicalReduction>1</mechanicalReduction>
  <maxVelocity>15.70</maxVelocity><!-- 150rpm -->
  <maxEffort>94.0</maxEffort><!-- 94Nm -->
  </actuator>
</transmission>
<transmission name="rleg_joint3_tran">
  <type>transmission_interface/SimpleTransmission</type>
  <joint name="rleg_joint3">
    <hardwareInterface>hardware_interface/EffortJointInterface</hardwareInterface>
  </joint>
  <actuator name="rleg_joint3_motor">
    <hardwareInterface>hardware_interface/EffortJointInterface</hardwareInterface>
    <mechanicalReduction>1</mechanicalReduction>
  <maxVelocity>15.70</maxVelocity><!-- 150rpm -->
  <maxEffort>94.0</maxEffort><!-- 94Nm -->
  </actuator>
</transmission>
<transmission name="rleg_joint4_tran">
  <type>transmission_interface/SimpleTransmission</type>
  <joint name="rleg_joint4">
    <hardwareInterface>hardware_interface/EffortJointInterface</hardwareInterface>
  </joint>
  <actuator name="rleg_joint4_motor">
    <hardwareInterface>hardware_interface/EffortJointInterface</hardwareInterface>
    <mechanicalReduction>1</mechanicalReduction>
  <maxVelocity>12.56</maxVelocity><!-- 150rpm -->
  <maxEffort>150.0</maxEffort><!-- 150Nm -->
  </actuator>
</transmission>
<transmission name="rleg_joint5_tran">
  <type>transmission_interface/SimpleTransmission</type>
  <joint name="rleg_joint5">
    <hardwareInterface>hardware_interface/EffortJointInterface</hardwareInterface>
  </joint>
  <actuator name="rleg_joint5_motor">
    <hardwareInterface>hardware_interface/EffortJointInterface</hardwareInterface>
    <mechanicalReduction>1</mechanicalReduction>
  <maxVelocity>8.97</maxVelocity><!-- 85rpm -->
  <maxEffort>36.0</maxEffort><!-- 36Nm -->
  </actuator>
</transmission>
<transmission name="rleg_joint6_tran">
  <type>transmission_interface/SimpleTransmission</type>
  <joint name="rleg_joint6">
    <hardwareInterface>hardware_interface/EffortJointInterface</hardwareInterface>
  </joint>
  <actuator name="rleg_joint6_motor">
    <hardwareInterface>hardware_interface/EffortJointInterface</hardwareInterface>
    <mechanicalReduction>1</mechanicalReduction>
  <maxVelocity>8.97</maxVelocity><!-- 85rpm -->
  <maxEffort>36.0</maxEffort><!-- 36Nm -->
  </actuator>
</transmission>

<!-- Visualization of Foot contacts -->
<gazebo reference="lleg_joint6_fixed_1">
  <visual>
    <plugin filename="librobofarmDrawForcePlugin.so" name="drawForcePlugin">
      <topicName>orca/lleg_foot_contact_1</topicName>
    </plugin>
  </visual>
</gazebo>
<gazebo reference="lleg_joint6_fixed_2">
  <visual>
    <plugin filename="librobofarmDrawForcePlugin.so" name="drawForcePlugin">
      <topicName>orca/lleg_foot_contact_2</topicName>
    </plugin>
  </visual>
</gazebo>
<gazebo reference="rleg_joint6_fixed_1">
  <visual>
    <plugin filename="librobofarmDrawForcePlugin.so" name="drawForcePlugin">
      <topicName>orca/rleg_foot_contact_1</topicName>
    </plugin>
  </visual>
</gazebo>
<gazebo reference="rleg_joint6_fixed_2">
  <visual>
    <plugin filename="librobofarmDrawForcePlugin.so" name="drawForcePlugin">
      <topicName>orca/rleg_foot_contact_2</topicName>
    </plugin>
  </visual>
</gazebo>
<gazebo reference="lleg_link6">
  <sensor name="orca/lleg_foot_contact_1" type="contact">
    <update_rate>100</update_rate>
    <plugin filename="librobofarmFootContactPlugin.so" name="contactPlugin"/>
    <contact>
      <collision>lleg_link6_fixed1_collision_1</collision>
    </contact>
  </sensor>
</gazebo>
<gazebo reference="lleg_link6">
  <sensor name="orca/lleg_foot_contact_2" type="contact">
    <update_rate>100</update_rate>
    <plugin filename="librobofarmFootContactPlugin.so" name="contactPlugin"/>
    <contact>
      <collision>lleg_link6_fixed1_collision_2</collision>
    </contact>
  </sensor>
</gazebo>
<gazebo reference="rleg_link6">
  <sensor name="orca/rleg_foot_contact_1" type="contact">
    <update_rate>100</update_rate>
    <plugin filename="librobofarmFootContactPlugin.so" name="contactPlugin"/>
    <contact>
      <collision>rleg_link6_fixed1_collision_1</collision>
    </contact>
  </sensor>
</gazebo>
<gazebo reference="rleg_link6">
  <sensor name="orca/rleg_foot_contact_2" type="contact">
    <update_rate>100</update_rate>
    <plugin filename="librobofarmFootContactPlugin.so" name="contactPlugin"/>
    <contact>
      <collision>rleg_link6_fixed2_collision_2</collision>
    </contact>
  </sensor>
</gazebo>
 <!-- RARM Gazebo Parts-->


 <transmission name="larm_joint1_tran">
  <type>transmission_interface/SimpleTransmission</type>
  <joint name="larm_joint1">
    <hardwareInterface>hardware_interface/EffortJointInterface</hardwareInterface>
  </joint>
  <actuator name="larm_joint1_motor">
    <hardwareInterface>hardware_interface/EffortJointInterface</hardwareInterface>
    <mechanicalReduction>1</mechanicalReduction>
    <maxVelocity>15.7</maxVelocity><!-- 150rpm -->
    <maxEffort>94.0</maxEffort><!-- 94Nm -->
  </actuator>
</transmission>
<transmission name="larm_joint2_tran">
  <type>transmission_interface/SimpleTransmission</type>
  <joint name="larm_joint2">
    <hardwareInterface>hardware_interface/EffortJointInterface</hardwareInterface>
  </joint>
  <actuator name="larm_joint2_motor">
    <hardwareInterface>hardware_interface/EffortJointInterface</hardwareInterface>
    <mechanicalReduction>1</mechanicalReduction>
    <maxVelocity>8.97</maxVelocity><!-- 85rpm -->
    <maxEffort>36.0</maxEffort><!-- 36Nm -->
  </actuator>
</transmission>
<transmission name="larm_joint3_tran">
  <type>transmission_interface/SimpleTransmission</type>
  <joint name="larm_joint3">
    <hardwareInterface>hardware_interface/EffortJointInterface</hardwareInterface>
  </joint>
  <actuator name="larm_joint3_motor">
    <hardwareInterface>hardware_interface/EffortJointInterface</hardwareInterface>
    <mechanicalReduction>1</mechanicalReduction>
    <maxVelocity>8.97</maxVelocity><!-- 85rpm -->
    <maxEffort>36.0</maxEffort><!-- 36Nm -->
  </actuator>
</transmission>
<transmission name="larm_joint4_tran">
  <type>transmission_interface/SimpleTransmission</type>
  <joint name="larm_joint4">
    <hardwareInterface>hardware_interface/EffortJointInterface</hardwareInterface>
  </joint>
  <actuator name="larm_joint4_motor">
    <hardwareInterface>hardware_interface/EffortJointInterface</hardwareInterface>
    <mechanicalReduction>1</mechanicalReduction>
    <maxVelocity>8.97</maxVelocity><!-- 85rpm -->
    <maxEffort>36.0</maxEffort><!-- 36Nm -->
  </actuator>
</transmission>
<transmission name="larm_joint5_tran">
  <type>transmission_interface/SimpleTransmission</type>
  <joint name="larm_joint5">
    <hardwareInterface>hardware_interface/EffortJointInterface</hardwareInterface>
  </joint>
  <actuator name="larm_joint5_motor">
    <hardwareInterface>hardware_interface/EffortJointInterface</hardwareInterface>
    <mechanicalReduction>1</mechanicalReduction>
    <maxVelocity>8.97</maxVelocity><!-- 85rpm -->
    <maxEffort>36.0</maxEffort><!-- 36Nm -->
  </actuator>
</transmission>
<transmission name="larm_joint6_tran">
  <type>transmission_interface/SimpleTransmission</type>
  <joint name="larm_joint6">
    <hardwareInterface>hardware_interface/EffortJointInterface</hardwareInterface>
  </joint>
  <actuator name="larm_joint6_motor">
    <hardwareInterface>hardware_interface/EffortJointInterface</hardwareInterface>
    <mechanicalReduction>1</mechanicalReduction>
    <maxVelocity>8.97</maxVelocity><!-- 85rpm -->
    <maxEffort>36.0</maxEffort><!-- 36Nm -->
  </actuator>
</transmission>
 <!-- RARM Gazebo Parts-->
 <transmission name="rarm_joint1_tran">
  <type>transmission_interface/SimpleTransmission</type>
  <joint name="rarm_joint1">
    <hardwareInterface>hardware_interface/EffortJointInterface</hardwareInterface>
  </joint>
  <actuator name="rarm_joint1_motor">
    <hardwareInterface>hardware_interface/EffortJointInterface</hardwareInterface>
    <mechanicalReduction>1</mechanicalReduction>
    <maxVelocity>15.7</maxVelocity><!-- 150rpm -->
    <maxEffort>94.0</maxEffort><!-- 94Nm -->
  </actuator>
</transmission>
<transmission name="rarm_joint2_tran">
  <type>transmission_interface/SimpleTransmission</type>
  <joint name="rarm_joint2">
    <hardwareInterface>hardware_interface/EffortJointInterface</hardwareInterface>
  </joint>
  <actuator name="rarm_joint2_motor">
    <hardwareInterface>hardware_interface/EffortJointInterface</hardwareInterface>
    <mechanicalReduction>1</mechanicalReduction>
    <maxVelocity>8.97</maxVelocity><!-- 85rpm -->
    <maxEffort>36.0</maxEffort><!-- 36Nm -->
  </actuator>
</transmission>
<transmission name="rarm_joint3_tran">
  <type>transmission_interface/SimpleTransmission</type>
  <joint name="rarm_joint3">
    <hardwareInterface>hardware_interface/EffortJointInterface</hardwareInterface>
  </joint>
  <actuator name="rarm_joint3_motor">
    <hardwareInterface>hardware_interface/EffortJointInterface</hardwareInterface>
    <mechanicalReduction>1</mechanicalReduction>
    <maxVelocity>8.97</maxVelocity><!-- 85rpm -->
    <maxEffort>36.0</maxEffort><!-- 36Nm -->
  </actuator>
</transmission>
<transmission name="rarm_joint4_tran">
  <type>transmission_interface/SimpleTransmission</type>
  <joint name="rarm_joint4">
    <hardwareInterface>hardware_interface/EffortJointInterface</hardwareInterface>
  </joint>
  <actuator name="rarm_joint4_motor">
    <hardwareInterface>hardware_interface/EffortJointInterface</hardwareInterface>
    <mechanicalReduction>1</mechanicalReduction>
    <maxVelocity>8.97</maxVelocity><!-- 85rpm -->
    <maxEffort>36.0</maxEffort><!-- 36Nm -->
  </actuator>
</transmission>
<transmission name="rarm_joint5_tran">
  <type>transmission_interface/SimpleTransmission</type>
  <joint name="rarm_joint5">
    <hardwareInterface>hardware_interface/EffortJointInterface</hardwareInterface>
  </joint>
  <actuator name="rarm_joint5_motor">
    <hardwareInterface>hardware_interface/EffortJointInterface</hardwareInterface>
    <mechanicalReduction>1</mechanicalReduction>
    <maxVelocity>8.97</maxVelocity><!-- 85rpm -->
    <maxEffort>36.0</maxEffort><!-- 36Nm -->
  </actuator>
</transmission>
<transmission name="rarm_joint6_tran">
  <type>transmission_interface/SimpleTransmission</type>
  <joint name="rarm_joint6">
    <hardwareInterface>hardware_interface/EffortJointInterface</hardwareInterface>
  </joint>
  <actuator name="rarm_joint6_motor">
    <hardwareInterface>hardware_interface/EffortJointInterface</hardwareInterface>
    <mechanicalReduction>1</mechanicalReduction>
    <maxVelocity>8.97</maxVelocity><!-- 85rpm -->
    <maxEffort>36.0</maxEffort><!-- 36Nm -->
  </actuator>
</transmission>

<transmission name="waist_yaw_joint_tran">
  <type>transmission_interface/SimpleTransmission</type>
  <joint name="waist_yaw_joint">
    <hardwareInterface>hardware_interface/EffortJointInterface</hardwareInterface>
  </joint>
  <actuator name="waist_yaw_joint_motor">
    <hardwareInterface>hardware_interface/EffortJointInterface</hardwareInterface>
    <mechanicalReduction>1</mechanicalReduction>
    <maxVelocity>8.97</maxVelocity><!-- 85rpm -->
    <maxEffort>36.0</maxEffort><!-- 36Nm -->
  </actuator>
  </transmission>
  
  <link name="base">
    <visual>
      <origin rpy="0 0 0" xyz="0 0 0"/>
      <geometry>
        <box size="0.001 0.001 0.001"/>
      </geometry>
    </visual>
  </link>
  <joint name="floating_base" type="fixed">
    <origin rpy="0 0 0" xyz="0 0 0"/>
    <parent link="base"/>
    <child link="base_link"/>
  </joint>

  <link name="imu_link">
    <inertial>
        <mass value="0.01"/>
        <origin rpy="0 0 0" xyz="0 0 0"/>
        <inertia ixx="0.000001" ixy="0" ixz="0" iyy="0.000001" iyz="0" izz="0.000001"/>
    </inertial>
    <visual>
        <origin rpy="0 0 0" xyz="0 0 0"/>
        <geometry>
            <box size="0.015 0.015 0.004"/>
        </geometry>
    </visual>
    <material name="orange">
        <color rgba="255 108 10 255"/>
    </material>
  </link>

  <joint name="imu_joint" type="fixed">
    <parent link="base_link"/>
    <child link="imu_link"/>
    <origin rpy="0 0 0" xyz="0 0 0"/>
  </joint>

  <link
    name="base_link">
    <inertial>
      <origin
        xyz="-8.47E-05 -9.16E-08 0.009519856"
        rpy="0 0 0" />
      <mass
        value="3.885338638" />
      <inertia
        ixx="0.014183021"
        ixy="-2.03E-06"
        ixz="9.88E-06"
        iyy="0.013799859"
        iyz="-1.06E-07"
        izz="0.014759617" />
    </inertial>
    <visual>
      <origin
        xyz="0 0 0"
        rpy="0 0 0" />
      <geometry>
        <mesh
          filename="package://orca_ydescription_3cm/meshes/base_link.STL" />
      </geometry>
      <material
        name="">
        <color
          rgba="1 1 1 1" />
      </material>
    </visual>
    <collision>
      <origin
        xyz="0 0 0"
        rpy="0 0 0" />
      <geometry>
        <mesh
          filename="package://orca_ydescription_3cm/meshes/base_link_cls.STL" />
      </geometry>
    </collision>
  </link>
  <link
    name="waist_yaw_link1">
    <inertial>
      <origin
        xyz="-2.46E-05 -0.195013197 0.000228684"
        rpy="0 0 0" />
      <mass
        value="11.03319241" />
      <inertia
        ixx="0.155358264"
        ixy="1.62E-05"
        ixz="1.34E-05"
        iyy="0.065422946"
        iyz="0.00091394"
        izz="0.179385252" />
    </inertial>
    <visual>
      <origin
        xyz="0 0 0"
        rpy="0 0 0" />
      <geometry>
        <mesh
          filename="package://orca_ydescription_3cm/meshes/waist_yaw_link1.STL" />
      </geometry>
      <material
        name="">
        <color
          rgba="1 1 1 1" />
      </material>
    </visual>
    <collision>
      <origin
        xyz="0 0 0"
        rpy="-1.571 0 0" />
      <geometry>
        <mesh
          filename="package://orca_ydescription_3cm/meshes/waist_yaw_link1_cls.STL" />
      </geometry>
    </collision>
  </link>
  <joint
    name="waist_yaw_joint"
    type="revolute">
    <origin
      xyz="0 0 0.078"
      rpy="-1.570796327 0 1.570796327" />
    <parent
      link="base_link" />
    <child
      link="waist_yaw_link1" />
    <axis
      xyz="0 1 0" />
    <limit
      lower="-1.571"
      upper="1.571"
      effort="36"
      velocity="8.9" />
    <dynamics
      damping="0.5"
      friction="0" />
  </joint>
  <link
    name="larm_link1">
    <inertial>
      <origin
        xyz="0.000439855 0.035850183 7.91E-06"
        rpy="0 0 0" />
      <mass
        value="0.576081" />
      <inertia
        ixx="0.000526742"
        ixy="-6.86E-06"
        ixz="-9.9E-08"
        iyy="0.000441561"
        iyz="9.44E-08"
        izz="0.00059525" />
    </inertial>
    <visual>
      <origin
        xyz="0 0 0"
        rpy="0 0 0" />
      <geometry>
        <mesh
          filename="package://orca_ydescription_3cm/meshes/larm_link1.STL" />
      </geometry>
      <material
        name="">
        <color
          rgba="1 1 1 1" />
      </material>
    </visual>
    <collision>
      <origin
        xyz="0 0 0"
        rpy="-1.571 0 0" />
      <geometry>
        <mesh
          filename="package://orca_ydescription_3cm/meshes/larm_link1_cls.STL" />
      </geometry>
    </collision>
  </link>
  <joint
    name="larm_joint1"
    type="revolute">
    <origin
      xyz="0.134953079 -0.295908076 0"
      rpy="1.745329252 1.570796327 0" />
    <parent
      link="waist_yaw_link1" />
    <child
      link="larm_link1" />
    <axis
      xyz="0 1 0" />
    <limit
      lower="-2.88"
      upper="2.88"
      effort="94"
      velocity="15.7" />
    <dynamics
      damping="0.5"
      friction="0" />
  </joint>
  <link
    name="larm_link2">
    <inertial>
      <origin
        xyz="-0.025633252 0.000250778 0.015716769"
        rpy="0 0 0" />
      <mass
        value="0.235909411" />
      <inertia
        ixx="0.000407461"
        ixy="1.71E-05"
        ixz="5.62E-05"
        iyy="0.000283692"
        iyz="-5.58E-06"
        izz="0.000496636" />
    </inertial>
    <visual>
      <origin
        xyz="0 0 0"
        rpy="0 0 0" />
      <geometry>
        <mesh
          filename="package://orca_ydescription_3cm/meshes/larm_link2.STL" />
      </geometry>
      <material
        name="">
        <color
          rgba="1 1 1 1" />
      </material>
    </visual>
    <collision>
      <origin
        xyz="0 0 0"
        rpy="-1.571 -1.571 0" />
      <geometry>
        <mesh
          filename="package://orca_ydescription_3cm/meshes/larm_link2_cls.STL" />
      </geometry>
    </collision>
  </link>
  <joint
    name="larm_joint2"
    type="revolute">
    <origin
      xyz="-0.0015 0.049998667 0"
      rpy="-3.141592654 -1.396263402 1.570796327" />
    <parent
      link="larm_link1" />
    <child
      link="larm_link2" />
    <axis
      xyz="0 1 0" />
    <limit
      lower="-0.17"
      upper="2.62"
      effort="36"
      velocity="8.9" />
    <dynamics
      damping="0.5"
      friction="0" />
  </joint>
  <link
    name="larm_link3">
    <inertial>
      <origin
        xyz="0.000500131 0.089700659 0.003086245"
        rpy="0 0 0" />
      <mass
        value="1.087367475" />
      <inertia
        ixx="0.002488913"
        ixy="1.03E-06"
        ixz="-1.79E-07"
        iyy="0.000722803"
        iyz="-0.000140073"
        izz="0.002308042" />
    </inertial>
    <visual>
      <origin
        xyz="0 0 0"
        rpy="0 0 0" />
      <geometry>
        <mesh
          filename="package://orca_ydescription_3cm/meshes/larm_link3.STL" />
      </geometry>
      <material
        name="">
        <color
          rgba="1 1 1 1" />
      </material>
    </visual>
    <collision>
      <origin
        xyz="0 0 0"
        rpy="-1.571 -1.571 0" />
      <geometry>
        <mesh
          filename="package://orca_ydescription_3cm/meshes/larm_link3_cls.STL" />
      </geometry>
    </collision>
  </link>
  <joint
    name="larm_joint3"
    type="revolute">
    <origin
      xyz="-0.0645 0 0.020001353"
      rpy="0 0 1.570796327" />
    <parent
      link="larm_link2" />
    <child
      link="larm_link3" />
    <axis
      xyz="0 1 0" />
    <limit
      lower="-2.79"
      upper="2.79"
      effort="36"
      velocity="8.9" />
    <dynamics
      damping="0.5"
      friction="0" />
  </joint>
  <link
    name="larm_link4">
    <inertial>
      <origin
        xyz="0.001911713 0.010161859 -0.056077982"
        rpy="0 0 0" />
      <mass
        value="0.631589507" />
      <inertia
        ixx="0.001429069"
        ixy="1.24E-05"
        ixz="1.98E-05"
        iyy="0.001379818"
        iyz="-0.000144233"
        izz="0.000967363" />
    </inertial>
    <visual>
      <origin
        xyz="0 0 0"
        rpy="0 0 0" />
      <geometry>
        <mesh
          filename="package://orca_ydescription_3cm/meshes/larm_link4.STL" />
      </geometry>
      <material
        name="">
        <color
          rgba="1 1 1 1" />
      </material>
    </visual>
    <collision>
      <origin
        xyz="0 0 0"
        rpy="1.571 0 0" />
      <geometry>
        <mesh
          filename="package://orca_ydescription_3cm/meshes/larm_link4_cls.STL" />
      </geometry>
    </collision>
  </link>
  <joint
    name="larm_joint4"
    type="revolute">
    <origin
      xyz="0 0.1835 0"
      rpy="1.570796327 0 0" />
    <parent
      link="larm_link3" />
    <child
      link="larm_link4" />
    <axis
      xyz="0 1 0" />
    <limit
      lower="-1.57"
      upper="1.57"
      effort="36"
      velocity="8.9" />
    <dynamics
      damping="0.5"
      friction="0" />
  </joint>
  <link
    name="larm_link5">
    <inertial>
      <origin
        xyz="-0.073159086 0.006187322 3.44E-06"
        rpy="0 0 0" />
      <mass
        value="0.451979036" />
      <inertia
        ixx="0.000269516"
        ixy="-0.000116707"
        ixz="-5.33E-08"
        iyy="0.000529737"
        iyz="2.9E-07"
        izz="0.000579657" />
    </inertial>
    <visual>
      <origin
        xyz="0 0 0"
        rpy="0 0 0" />
      <geometry>
        <mesh
          filename="package://orca_ydescription_3cm/meshes/larm_link5.STL" />
      </geometry>
      <material
        name="">
        <color
          rgba="1 1 1 1" />
      </material>
    </visual>
    <collision>
      <origin
        xyz="0 0 0"
        rpy="-1.571 -1.571 0" />
      <geometry>
        <mesh
          filename="package://orca_ydescription_3cm/meshes/larm_link5_cls.STL" />
      </geometry>
    </collision>
  </link>
  <joint
    name="larm_joint5"
    type="revolute">
    <origin
      xyz="0 0 -0.075"
      rpy="-1.570796327 -1.570796327 0" />
    <parent
      link="larm_link4" />
    <child
      link="larm_link5" />
    <axis
      xyz="0 1 0" />
    <limit
      lower="-0.35"
      upper="1.57"
      effort="36"
      velocity="8.9" />
    <dynamics
      damping="0.5"
      friction="0" />
  </joint>
  <link
    name="larm_link6">
    <inertial>
      <origin
        xyz="0.000892339 0.105967647 3.11E-05"
        rpy="0 0 0" />
      <mass
        value="0.830188707" />
      <inertia
        ixx="0.002308313"
        ixy="2.57E-05"
        ixz="2.53E-07"
        iyy="0.000612406"
        iyz="6.74E-07"
        izz="0.002014112" />
    </inertial>
    <visual>
      <origin
        xyz="0 0 0"
        rpy="0 0 0" />
      <geometry>
        <mesh
          filename="package://orca_ydescription_3cm/meshes/larm_link6.STL" />
      </geometry>
      <material
        name="">
        <color
          rgba="1 1 1 1" />
      </material>
    </visual>
    <collision>
      <origin
        xyz="0 0 0"
        rpy="0 0 0" />
      <geometry>
        <mesh
          filename="package://orca_ydescription_3cm/meshes/larm_link6_cls.STL" />
      </geometry>
    </collision>
  </link>
  <joint
    name="larm_joint6"
    type="revolute">
    <origin
      xyz="-0.105 0 0"
      rpy="1.570796327 -1.570796327 0" />
    <parent
      link="larm_link5" />
    <child
      link="larm_link6" />
    <axis
      xyz="0 1 0" />
    <limit
      lower="-2.79"
      upper="2.79"
      effort="36"
      velocity="8.9" />
    <dynamics
      damping="0.5"
      friction="0" />
  </joint>
  <link
    name="rarm_link1">
    <inertial>
      <origin
        xyz="0.000439873 -0.03585016 7.93E-06"
        rpy="0 0 0" />
      <mass
        value="0.576081148" />
      <inertia
        ixx="0.000526742"
        ixy="6.86E-06"
        ixz="-9.88E-08"
        iyy="0.000441561"
        iyz="-9.44E-08"
        izz="0.000595249" />
    </inertial>
    <visual>
      <origin
        xyz="0 0 0"
        rpy="0 0 0" />
      <geometry>
        <mesh
          filename="package://orca_ydescription_3cm/meshes/rarm_link1.STL" />
      </geometry>
      <material
        name="">
        <color
          rgba="1 1 1 1" />
      </material>
    </visual>
    <collision>
      <origin
        xyz="0 0 0"
        rpy="1.571 0 0" />
      <geometry>
        <mesh
          filename="package://orca_ydescription_3cm/meshes/rarm_link1_cls.STL" />
      </geometry>
    </collision>
  </link>
  <joint
    name="rarm_joint1"
    type="revolute">
    <origin
      xyz="-0.134953079 -0.295908076 0"
      rpy="1.396263402 1.570796327 0" />
    <parent
      link="waist_yaw_link1" />
    <child
      link="rarm_link1" />
    <axis
      xyz="0 1 0" />
    <limit
      lower="-2.88"
      upper="2.88"
      effort="94"
      velocity="15.7" />
    <dynamics
      damping="0.5"
      friction="0" />
  </joint>
  <link
    name="rarm_link2">
    <inertial>
      <origin
        xyz="-0.02563088 0.000253501 -0.015720954"
        rpy="0 0 0" />
      <mass
        value="0.235938732" />
      <inertia
        ixx="0.000407458"
        ixy="1.71E-05"
        ixz="-5.62E-05"
        iyy="0.000283649"
        iyz="5.56E-06"
        izz="0.000496642" />
    </inertial>
    <visual>
      <origin
        xyz="0 0 0"
        rpy="0 0 0" />
      <geometry>
        <mesh
          filename="package://orca_ydescription_3cm/meshes/rarm_link2.STL" />
      </geometry>
      <material
        name="">
        <color
          rgba="1 1 1 1" />
      </material>
    </visual>
    <collision>
      <origin
        xyz="0 0 0"
        rpy="-1.571 -1.571 0" />
      <geometry>
        <mesh
          filename="package://orca_ydescription_3cm/meshes/rarm_link2_cls.STL" />
      </geometry>
    </collision>
  </link>
  <joint
    name="rarm_joint2"
    type="revolute">
    <origin
      xyz="-0.0015 -0.049998667 0"
      rpy="0 -1.396263402 -1.570796327" />
    <parent
      link="rarm_link1" />
    <child
      link="rarm_link2" />
    <axis
      xyz="0 -1 0" />
    <limit
      lower="-0.17"
      upper="2.62"
      effort="36"
      velocity="8.9" />
    <dynamics
      damping="0.5"
      friction="0" />
  </joint>
  <link
    name="rarm_link3">
    <inertial>
      <origin
        xyz="0.000500342 0.089701323 -0.003086662"
        rpy="0 0 0" />
      <mass
        value="1.087374142" />
      <inertia
        ixx="0.002488887"
        ixy="1.05E-06"
        ixz="1.6E-07"
        iyy="0.000722818"
        iyz="0.000140053"
        izz="0.002308041" />
    </inertial>
    <visual>
      <origin
        xyz="0 0 0"
        rpy="0 0 0" />
      <geometry>
        <mesh
          filename="package://orca_ydescription_3cm/meshes/rarm_link3.STL" />
      </geometry>
      <material
        name="">
        <color
          rgba="1 1 1 1" />
      </material>
    </visual>
    <collision>
      <origin
        xyz="0 0 0"
        rpy="-1.571 -1.571 0" />
      <geometry>
        <mesh
          filename="package://orca_ydescription_3cm/meshes/rarm_link3_cls.STL" />
      </geometry>
    </collision>
  </link>
  <joint
    name="rarm_joint3"
    type="revolute">
    <origin
      xyz="-0.0645 0 -0.020001353"
      rpy="0 0 1.570796327" />
    <parent
      link="rarm_link2" />
    <child
      link="rarm_link3" />
    <axis
      xyz="0 1 0" />
    <limit
      lower="-2.79"
      upper="2.79"
      effort="36"
      velocity="8.9" />
    <dynamics
      damping="0.5"
      friction="0" />
  </joint>
  <link
    name="rarm_link4">
    <inertial>
      <origin
        xyz="0.001908352 -0.010158385 -0.056080165"
        rpy="0 0 0" />
      <mass
        value="0.631620451" />
      <inertia
        ixx="0.001429094"
        ixy="-1.24E-05"
        ixz="1.98E-05"
        iyy="0.00137982"
        iyz="0.000144214"
        izz="0.000967415" />
    </inertial>
    <visual>
      <origin
        xyz="0 0 0"
        rpy="0 0 0" />
      <geometry>
        <mesh
          filename="package://orca_ydescription_3cm/meshes/rarm_link4.STL" />
      </geometry>
      <material
        name="">
        <color
          rgba="1 1 1 1" />
      </material>
    </visual>
    <collision>
      <origin
        xyz="0 0 0"
        rpy="1.571 0 0" />
      <geometry>
        <mesh
          filename="package://orca_ydescription_3cm/meshes/rarm_link4_cls.STL" />
      </geometry>
    </collision>
  </link>
  <joint
    name="rarm_joint4"
    type="revolute">
    <origin
      xyz="0 0.1835 0"
      rpy="1.570796327 0 0" />
    <parent
      link="rarm_link3" />
    <child
      link="rarm_link4" />
    <axis
      xyz="0 1 0" />
    <limit
      lower="-1.57"
      upper="1.57"
      effort="36"
      velocity="8.9" />
    <dynamics
      damping="0.5"
      friction="0" />
  </joint>
  <link
    name="rarm_link5">
    <inertial>
      <origin
        xyz="-0.073159111 0.006187367 -3.6E-06"
        rpy="0 0 0" />
      <mass
        value="0.451977745" />
      <inertia
        ixx="0.000269514"
        ixy="-0.000116709"
        ixz="5.33E-08"
        iyy="0.00052974"
        iyz="-2.91E-07"
        izz="0.000579657" />
    </inertial>
    <visual>
      <origin
        xyz="0 0 0"
        rpy="0 0 0" />
      <geometry>
        <mesh
          filename="package://orca_ydescription_3cm/meshes/rarm_link5.STL" />
      </geometry>
      <material
        name="">
        <color
          rgba="1 1 1 1" />
      </material>
    </visual>
    <collision>
      <origin
        xyz="0 0 0"
        rpy="-1.571 -1.571 0" />
      <geometry>
        <mesh
          filename="package://orca_ydescription_3cm/meshes/rarm_link5_cls.STL" />
      </geometry>
    </collision>
  </link>
  <joint
    name="rarm_joint5"
    type="revolute">
    <origin
      xyz="0 0 -0.075"
      rpy="-1.570796327 -1.570796327 0" />
    <parent
      link="rarm_link4" />
    <child
      link="rarm_link5" />
    <axis
      xyz="0 1 0" />
    <limit
      lower="-0.35"
      upper="1.57"
      effort="36"
      velocity="8.9" />
    <dynamics
      damping="0.5"
      friction="0" />
  </joint>
  <link
    name="rarm_link6">
    <inertial>
      <origin
        xyz="-0.000892336 0.105967653 3.1E-05"
        rpy="0 0 0" />
      <mass
        value="0.830188258" />
      <inertia
        ixx="0.002308314"
        ixy="-2.57E-05"
        ixz="-2.53E-07"
        iyy="0.000612406"
        iyz="6.73E-07"
        izz="0.002014112" />
    </inertial>
    <visual>
      <origin
        xyz="0 0 0"
        rpy="0 0 0" />
      <geometry>
        <mesh
          filename="package://orca_ydescription_3cm/meshes/rarm_link6.STL" />
      </geometry>
      <material
        name="">
        <color
          rgba="1 1 1 1" />
      </material>
    </visual>
    <collision>
      <origin
        xyz="0 0 0"
        rpy="0 0 0" />
      <geometry>
        <mesh
          filename="package://orca_ydescription_3cm/meshes/rarm_link6_cls.STL" />
      </geometry>
    </collision>
  </link>
  <joint
    name="rarm_joint6"
    type="revolute">
    <origin
      xyz="-0.105 0 0"
      rpy="1.570796327 -1.570796327 0" />
    <parent
      link="rarm_link5" />
    <child
      link="rarm_link6" />
    <axis
      xyz="0 1 0" />
    <limit
      lower="-2.79"
      upper="2.79"
      effort="36"
      velocity="8.9" />
    <dynamics
      damping="0.5"
      friction="0" />
  </joint>
  <link
    name="head_link1">
    <inertial>
      <origin
        xyz="0 0 0"
        rpy="0 0 0" />
      <mass
        value="0.000534071" />
      <inertia
        ixx="5.34E-09"
        ixy="5.17E-26"
        ixz="1.62E-40"
        iyy="5.34E-09"
        iyz="2.37E-41"
        izz="5.34E-09" />
    </inertial>
    <visual>
      <origin
        xyz="0 0 0"
        rpy="0 0 0" />
      <geometry>
        <mesh
          filename="package://orca_ydescription_3cm/meshes/head_link1.STL" />
      </geometry>
      <material
        name="">
        <color
          rgba="1 1 1 1" />
      </material>
    </visual>
    <collision>
      <origin
        xyz="0 0 0"
        rpy="0 0 0" />
      <geometry>
        <mesh
          filename="package://orca_ydescription_3cm/meshes/head_link1.STL" />
      </geometry>
    </collision>
  </link>
  <joint
    name="head_joint1"
    type="fixed">
    <origin
      xyz="0 -0.4656 -0.0086"
      rpy="-1.571 -1.571 0" />
    <parent
      link="waist_yaw_link1" />
    <child
      link="head_link1" />
    <axis
      xyz="1 0 0" />
    <limit
      lower="-0.349"
      upper="0.349"
      effort="3"
      velocity="8" />
    <dynamics
      damping="0.5"
      friction="0" />
  </joint>
  <link
    name="head_link2">
    <inertial>
      <origin
        xyz="1.11E-16 2.43E-17 0"
        rpy="0 0 0" />
      <mass
        value="0.000534071" />
      <inertia
        ixx="5.34E-09"
        ixy="3.88E-26"
        ixz="5.74E-42"
        iyy="5.34E-09"
        iyz="-9.95E-41"
        izz="5.34E-09" />
    </inertial>
    <visual>
      <origin
        xyz="0 0 0"
        rpy="0 0 0" />
      <geometry>
        <mesh
          filename="package://orca_ydescription_3cm/meshes/head_link2.STL" />
      </geometry>
      <material
        name="">
        <color
          rgba="1 1 1 1" />
      </material>
    </visual>
    <collision>
      <origin
        xyz="0 0 0"
        rpy="0 0 0" />
      <geometry>
        <mesh
          filename="package://orca_ydescription_3cm/meshes/head_link2.STL" />
      </geometry>
    </collision>
  </link>
  <joint
    name="head_joint2"
    type="fixed">
    <!-- <origin
      xyz="0 0 0"
      rpy="1.570796327 -1.527598468 -1.425482991" /> -->
    <origin
      xyz="0 0 0"
      rpy="1.570796327 -1.5707 -1.5707" />
    <parent
      link="head_link1" />
    <child
      link="head_link2" />
    <axis
      xyz="0 1 0" />
    <limit
      lower="-0.349"
      upper="0.349"
      effort="3"
      velocity="8" />
    <dynamics
      damping="0.5"
      friction="0" />
  </joint>
  <link
    name="head_link3">
    <inertial>
      <origin
        xyz="-0.000672526 -8.45E-05 0.04525922"
        rpy="0 0 0" />
      <mass
        value="0.960823777" />
      <inertia
        ixx="0.004598234"
        ixy="2.38E-07"
        ixz="2.43E-05"
        iyy="0.002226063"
        iyz="5.69E-07"
        izz="0.004802875" />
    </inertial>
    <visual>
      <origin
        xyz="0 0 0"
        rpy="0 0 0" />
      <geometry>
        <mesh
          filename="package://orca_ydescription_3cm/meshes/head_link3.STL" />
      </geometry>
      <material
        name="">
        <color
          rgba="1 1 1 1" />
      </material>
    </visual>
    <collision>
      <origin
        xyz="0 0 0"
        rpy="0 0 0" />
      <geometry>
        <mesh
          filename="package://orca_ydescription_3cm/meshes/head_link3.STL" />
      </geometry>
    </collision>
  </link>
  <joint
    name="head_joint3"
    type="fixed">
    <!-- <origin
      xyz="0 0 0"
      rpy="0.043197859 -1.570796327 0" /> -->
    <origin
      xyz="0 0 0"
      rpy="3.142 -1.570796327 0" />
    <parent
      link="head_link2" />
    <child
      link="head_link3" />
    <axis
      xyz="0 0 1" />
    <limit
      lower="-0.523"
      upper="0.349"
      effort="3"
      velocity="8" />
    <dynamics
      damping="0.5"
      friction="0" />
  </joint>
  <link
    name="lleg_link1">
    <inertial>
      <origin
        xyz="-0.0414231544911224 -0.00514312296824225 -0.0912263689528675"
        rpy="0 0 0" />
      <mass
        value="1.86152386862835" />
      <inertia
        ixx="0.00788495380545202"
        ixy="0.000390927666606671"
        ixz="-0.0037428777228417"
        iyy="0.0134626686367762"
        iyz="0.000913004782821924"
        izz="0.00858048562013347" />
    </inertial>
    <visual>
      <origin
        xyz="0 0 0"
        rpy="0 0 0" />
      <geometry>
        <mesh
          filename="package://orca_ydescription_3cm/meshes/lleg_link1.STL" />
      </geometry>
      <material
        name="">
        <color
          rgba="1 1 1 1" />
      </material>
    </visual>
    <collision>
      <origin
        xyz="0 0 0"
        rpy="-1.571 0 0" />
      <geometry>
        <mesh
          filename="package://orca_ydescription_3cm/meshes/lleg_link1_cls.STL" />
      </geometry>
    </collision>
  </link>
  <joint
    name="lleg_joint1"
    type="revolute">
    <origin
      xyz="0 0.125 0"
      rpy="0 0 0" />
    <parent
      link="base_link" />
    <child
      link="lleg_link1" />
    <axis
      xyz="0 -1 0" />
    <limit
      lower="-1.22"
      upper="1.92"
      effort="150"
      velocity="14.65" />
    <dynamics
      damping="0.5"
      friction="0" />
  </joint>
  <link
    name="lleg_link2">
    <inertial>
      <origin
        xyz="-0.006954122 -0.00602969 5.86E-06"
        rpy="0 0 0" />
      <mass
        value="1.300432803" />
      <inertia
        ixx="0.002954606"
        ixy="4.07E-05"
        ixz="-1.18E-06"
        iyy="0.001657068"
        iyz="-1.51E-05"
        izz="0.002286791" />
    </inertial>
    <visual>
      <origin
        xyz="0 0 0"
        rpy="0 0 0" />
      <geometry>
        <mesh
          filename="package://orca_ydescription_3cm/meshes/lleg_link2.STL" />
      </geometry>
      <material
        name="">
        <color
          rgba="1 1 1 1" />
      </material>
    </visual>
    <collision>
      <origin
        xyz="0 0 0"
        rpy="0 0 0" />
      <geometry>
        <mesh
          filename="package://orca_ydescription_3cm/meshes/lleg_link2_cls.STL" />
      </geometry>
    </collision>
  </link>
  <joint
    name="lleg_joint2"
    type="revolute">
    <origin
      xyz="0 0 -0.1415"
      rpy="-1.570796327 -1.570796327 0" />
    <parent
      link="lleg_link1" />
    <child
      link="lleg_link2" />
    <axis
      xyz="0 -1 0" />
    <limit
      lower="-1.57"
      upper="0.26"
      effort="94"
      velocity="15.7" />
    <dynamics
      damping="0.5"
      friction="0" />
  </joint>
  <link
    name="lleg_link3">
    <inertial>
      <origin
        xyz="-0.003193462 0.118677095 0.011628846"
        rpy="0 0 0" />
      <mass
        value="3.1861688" />
      <inertia
        ixx="0.017966441"
        ixy="-0.001615058"
        ixz="0.000327065"
        iyy="0.007797636"
        iyz="0.001538728"
        izz="0.018560511" />
    </inertial>
    <visual>
      <origin
        xyz="0 0 0"
        rpy="0 0 0" />
      <geometry>
        <mesh
          filename="package://orca_ydescription_3cm/meshes/lleg_link3.STL" />
      </geometry>
      <material
        name="">
        <color
          rgba="1 1 1 1" />
      </material>
    </visual>
    <collision>
      <origin
        xyz="0 0 0"
        rpy="-1.571 0 0" />
      <geometry>
        <mesh
          filename="package://orca_ydescription_3cm/meshes/lleg_link3_cls.STL" />
      </geometry>
    </collision>
  </link>
  <joint
    name="lleg_joint3"
    type="revolute">
    <origin
      xyz="-0.0275 0 0"
      rpy="0 0 1.570796327" />
    <parent
      link="lleg_link2" />
    <child
      link="lleg_link3" />
    <axis
      xyz="0 1 0" />
    <limit
      lower="-2.6"
      upper="0.44"
      effort="94"
      velocity="15.7" />
    <dynamics
      damping="0.5"
      friction="0" />
  </joint>
  <link
    name="lleg_link4">
    <inertial>
      <origin
        xyz="-0.00152225065184456 0.00361293636958301 -0.132559591969628"
        rpy="0 0 0" />
      <mass
        value="1.83999293748654" />
      <inertia
        ixx="0.0108841825322086"
        ixy="3.26789708116387E-05"
        ixz="6.26384201397711E-06"
        iyy="0.0107317521963956"
        iyz="-0.000774034714238863"
        izz="0.00187312853479281" />
    </inertial>
    <visual>
      <origin
        xyz="0 0 0"
        rpy="0 0 0" />
      <geometry>
        <mesh
          filename="package://orca_ydescription_3cm/meshes/lleg_link4.STL" />
      </geometry>
      <material
        name="">
        <color
          rgba="1 1 1 1" />
      </material>
    </visual>
    <collision>
      <origin
        xyz="0 0 0"
        rpy="1.57 0 3.14" />
      <geometry>
        <mesh
          filename="package://orca_ydescription_3cm/meshes/lleg_link4_cls.STL" />
      </geometry>
    </collision>
  </link>
  <joint
    name="lleg_joint4"
    type="revolute">
    <origin
      xyz="0 0.267721631 0"
      rpy="1.570796327 0 0" />
    <parent
      link="lleg_link3" />
    <child
      link="lleg_link4" />
    <axis
      xyz="0 -1 0" />
    <limit
      lower="-2.093"
      upper="0.614"
      effort="150"
      velocity="14.65" />
    <dynamics
      damping="0.5"
      friction="0" />
  </joint>
  <link
    name="lleg_link5">
   <inertial>
      <origin
        xyz="-0.0116562233297665 -6.36324763887697E-09 -0.0639780361362227"
        rpy="0 0 0" />
      <mass
        value="0.815248914632693" />
      <inertia
        ixx="0.00082295416547413"
        ixy="-1.34051192048482E-09"
        ixz="-6.66083044645393E-05"
        iyy="0.000796113865945101"
        iyz="8.17247670208792E-11"
        izz="0.000672385880513338" />
    </inertial>
    <visual>
      <origin
        xyz="0 0 0"
        rpy="0 0 0" />
      <geometry>
        <mesh
          filename="package://orca_ydescription_3cm/meshes/lleg_link5.STL" />
      </geometry>
      <material
        name="">
        <color
          rgba="1 1 1 1" />
      </material>
    </visual>
    <collision>
      <origin
        xyz="0 0 0"
        rpy="1.57 0 1.57" />
      <geometry>
        <mesh
          filename="package://orca_ydescription_3cm/meshes/lleg_link5_cls.STL" />
      </geometry>
    </collision>
  </link>
  <joint
    name="lleg_joint5"
    type="revolute">
    <origin
      xyz="0 -0.00899999999999999 -0.262"
      rpy="0 0 0" />
    <parent
      link="lleg_link4" />
    <child
      link="lleg_link5" />
    <axis
      xyz="0 -1 0" />
    <!-- <limit
      lower="-0.56"
      upper="0.45"
      effort="36"
      velocity="8.9" /> -->
   <limit
      lower="-1.57"
      upper="1.57"
      effort="60"
      velocity="13.188" />
    <dynamics
      damping="0.5"
      friction="0" />
  </joint>
  <link
    name="lleg_link6">
    <inertial>
      <origin
        xyz="0.0329782831091455 -0.00171847078047017 -0.0558702414044165"
        rpy="0 0 0" />
      <mass
        value="0.434267885629283" />
      <inertia
        ixx="0.000334685855038701"
        ixy="7.20797699185881E-05"
        ixz="6.83506213943439E-05"
        iyy="0.00201538958940841"
        iyz="-3.73049296534096E-06"
        izz="0.0021371210371888" />
    </inertial>
    <visual>
      <origin
        xyz="0 0 0"
        rpy="0 0 0" />
      <geometry>
        <mesh
          filename="package://orca_ydescription_3cm/meshes/lleg_link6.STL" />
      </geometry>
      <material
        name="">
        <color
          rgba="1 1 1 1" />
      </material>
    </visual>
    <collision>
      <origin
        xyz="0 0 0"
        rpy="1.57 0 1.57" />
      <geometry>
        <mesh
          filename="package://orca_ydescription_3cm/meshes/lleg_link6_cls.STL" />
      </geometry>
    </collision>
  </link>
  <joint
    name="lleg_joint6"
    type="revolute">
    <origin
      xyz="0.0105 0 -0.0710000000000001"
      rpy="0 0 0" />
    <parent
      link="lleg_link5" />
    <child
      link="lleg_link6" />
    <axis
      xyz="1 0 0" />
   <limit
      lower="-0.61"
      upper="0.61"
      effort="36"
      velocity="8.164" />
    <dynamics
      damping="0.5"
      friction="0" />
  </joint>
  <link
    name="rleg_link1">
    <inertial>
      <origin
        xyz="-0.041423 0.0051432 -0.091227"
        rpy="0 0 0" />
      <mass
        value="1.8615" />
      <inertia
        ixx="0.007885"
        ixy="-0.00039093"
        ixz="-0.0037429"
        iyy="0.013463"
        iyz="-0.00091301"
        izz="0.0085805" />
    </inertial>
    <visual>
      <origin
        xyz="0 0 0"
        rpy="0 0 0" />
      <geometry>
        <mesh
          filename="package://orca_ydescription_3cm/meshes/rleg_link1.STL" />
      </geometry>
      <material
        name="">
        <color
          rgba="1 1 1 1" />
      </material>
    </visual>
    <collision>
      <origin
        xyz="0 0 0"
        rpy="1.571 3.1416 0" />
      <geometry>
        <mesh
          filename="package://orca_ydescription_3cm/meshes/rleg_link1_cls.STL" />
      </geometry>
    </collision>
  </link>
  <joint
    name="rleg_joint1"
    type="revolute">
    <origin
      xyz="0 -0.125 0"
      rpy="0 0 0" />
    <parent
      link="base_link" />
    <child
      link="rleg_link1" />
    <axis
      xyz="0 -1 0" />
    <limit
      lower="-1.22"
      upper="1.92"
      effort="150"
      velocity="14.65" />
    <dynamics
      damping="0.5"
      friction="0" />
  </joint>
  <link
    name="rleg_link2">
    <inertial>
      <origin
        xyz="0.006046 0.0038573 -5.86E-06"
        rpy="0 0 0" />
      <mass
        value="1.3004" />
      <inertia
        ixx="0.0029546"
        ixy="4.07E-05"
        ixz="1.19E-06"
        iyy="0.001657"
        iyz="1.51E-05"
        izz="0.0022868" />
    </inertial>
    <visual>
      <origin
        xyz="0 0 0"
        rpy="0 0 0" />
      <geometry>
        <mesh
          filename="package://orca_ydescription_3cm/meshes/rleg_link2.STL" />
      </geometry>
      <material
        name="">
        <color
          rgba="1 1 1 1" />
      </material>
    </visual>
    <collision>
      <origin
        xyz="0 0 0"
        rpy="0 3.1416 0" />
      <geometry>
        <mesh
          filename="package://orca_ydescription_3cm/meshes/rleg_link2_cls.STL" />
      </geometry>
    </collision>
  </link>
  <joint
    name="rleg_joint2"
    type="revolute">
    <!-- <origin
      xyz="-0.009887084 0 -0.1545"
      rpy="-1.570796327 -1.570796327 0" /> -->
    <origin
      xyz="0 0 -0.1415"
      rpy="-1.570796327 -1.570796327 0" />
    <parent
      link="rleg_link1" />
    <child
      link="rleg_link2" />
    <axis
      xyz="0 1 0" />
    <limit
      lower="-1.57"
      upper="0.26"
      effort="94"
      velocity="15.7" />
    <dynamics
      damping="0.5"
      friction="0" />
  </joint>
  <link
    name="rleg_link3">
    <inertial>
      <origin
        xyz="-0.003193895 0.118677583 0.011629722"
        rpy="0 0 0" />
      <mass
        value="3.186287653" />
      <inertia
        ixx="0.017966915"
        ixy="-0.001614775"
        ixz="-0.000327007"
        iyy="0.007797823"
        iyz="-0.001538767"
        izz="0.018561129" />
    </inertial>
    <visual>
      <origin
        xyz="0 0 0"
        rpy="0 0 0" />
      <geometry>
        <mesh
          filename="package://orca_ydescription_3cm/meshes/rleg_link3.STL" />
      </geometry>
      <material
        name="">
        <color
          rgba="1 1 1 1" />
      </material>
    </visual>
    <collision>
      <origin
        xyz="0 0 0"
        rpy="-1.571 3.1416 0" />
      <geometry>
        <mesh
          filename="package://orca_ydescription_3cm/meshes/rleg_link3_cls.STL" />
      </geometry>
    </collision>
  </link>
  <joint
    name="rleg_joint3"
    type="revolute">
    <!-- <origin
      xyz="-0.0145 0.009887084 0"
      rpy="0 0 1.570796327" /> -->
    <origin
      xyz="-0.0275 0 0"
      rpy="0 0 1.570796327" />
    <parent
      link="rleg_link2" />
    <child
      link="rleg_link3" />
    <axis
      xyz="0 -1 0" />
    <limit
      lower="-2.6"
      upper="0.44"
      effort="94"
      velocity="15.7" />
    <dynamics
      damping="0.5"
      friction="0" />
  </joint>
  <link
    name="rleg_link4">
     <inertial>
      <origin
        xyz="-0.00152224198898753 -0.00361293807887636 -0.132559598337074"
        rpy="0 0 0" />
      <mass
        value="1.83999283796375" />
      <inertia
        ixx="0.0108841810313571"
        ixy="-3.26794362840042E-05"
        ixz="6.26554151584445E-06"
        iyy="0.0107317506544257"
        iyz="0.000774034556495078"
        izz="0.00187312795377983" />
    </inertial>
    <visual>
      <origin
        xyz="0 0 0"
        rpy="0 0 0" />
      <geometry>
        <mesh
          filename="package://orca_ydescription_3cm/meshes/rleg_link4.STL" />
      </geometry>
      <material
        name="">
        <color
          rgba="1 1 1 1" />
      </material>
    </visual>
    <collision>
      <origin
        xyz="0 0 0"
        rpy="1.57 0 3.14" />
      <geometry>
        <mesh
          filename="package://orca_ydescription_3cm/meshes/rleg_link4_cls.STL" />
      </geometry>
    </collision>
  </link>
  <joint
    name="rleg_joint4"
    type="revolute">
    <origin
      xyz="0 0.267721631 0"
      rpy="1.571 0 0" />
    <parent
      link="rleg_link3" />
    <child
      link="rleg_link4" />
    <axis
      xyz="0 -1 0" />
    <limit
      lower="-2.093"
      upper="0.614"
      effort="150"
      velocity="14.65" />
    <dynamics
      damping="0.5"
      friction="0" />
  </joint>
   <link
    name="rleg_link5">
   <inertial>
      <origin
        xyz="-0.011656 -6.3716E-09 -0.063978"
        rpy="0 0 0" />
      <mass
        value="0.81525" />
      <inertia
        ixx="0.00082295"
        ixy="-1.3405E-09"
        ixz="-6.6608E-05"
        iyy="0.00079611"
        iyz="8.2102E-11"
        izz="0.00067239" />
    </inertial>
    <visual>
      <origin
        xyz="0 0 0"
        rpy="0 0 0" />
      <geometry>
        <mesh
          filename="package://orca_ydescription_3cm/meshes/rleg_link5.STL" />
      </geometry>
      <material
        name="">
        <color
          rgba="1 1 1 1" />
      </material>
    </visual>
    <collision>
      <origin
        xyz="0 0 0"
        rpy="1.57 0 1.57" />
      <geometry>
        <mesh
          filename="package://orca_ydescription_3cm/meshes/rleg_link5_cls.STL" />
      </geometry>
    </collision>
  </link>
  <joint
    name="rleg_joint5"
    type="revolute">
    <origin
      xyz="0 0.009 -0.262"
      rpy="0 0 0" />
    <parent
      link="rleg_link4" />
    <child
      link="rleg_link5" />
    <axis
      xyz="0 -1 0" />
    <limit
      lower="-1.57"
      upper="1.57"
      effort="60"
      velocity="13.188" />
    <dynamics
      damping="0.0" 
      friction="0"/>
  </joint>
  <link
    name="rleg_link6">
   <inertial>
      <origin
        xyz="0.0329972527999862 0.00171980256045553 -0.0558710536369997"
        rpy="0 0 0" />
      <mass
        value="0.434289966675498" />
      <inertia
        ixx="0.000334748816151449"
        ixy="-7.21677807280528E-05"
        ixz="6.83693729510625E-05"
        iyy="0.00201586715973069"
        iyz="3.72090657692404E-06"
        izz="0.00213763863113348" />
    </inertial>
    <visual>
      <origin
        xyz="0 0 0"
        rpy="0 0 0" />
      <geometry>
        <mesh
          filename="package://orca_ydescription_3cm/meshes/rleg_link6.STL" />
      </geometry>
      <material
        name="">
        <color
          rgba="1 1 1 1" />
      </material>
    </visual>
    <collision>
      <origin
        xyz="0 0 0"
        rpy="1.57 0 1.57" />
      <geometry>
        <mesh
          filename="package://orca_ydescription_3cm/meshes/rleg_link6_cls.STL" />
      </geometry>
    </collision>
  </link>
  <joint
    name="rleg_joint6"
    type="revolute">
    <origin
      xyz="0.0105 0 -0.071"
      rpy="0 0 0" />
    <parent
      link="rleg_link5" />
    <child
      link="rleg_link6" />
    <axis
      xyz="1 0 0" />
    <limit
      lower="-0.61"
      upper="0.61"
      effort="36"
      velocity="8.164" />
    <dynamics
      damping="0.5"
      friction="0" />
  </joint>
</robot>
